<?xml version="1.0" encoding="utf-8"?>
<!-- This URDF was automatically created by SolidWorks to URDF Exporter! Originally created by Stephen Brawner (brawner@gmail.com) 
     Commit Version: 1.6.0-4-g7f85cfe  Build Version: 1.6.7995.38578
     For more information, please see http://wiki.ros.org/sw_urdf_exporter -->
<robot
  name="F4-1000C">
  <link
    name="base_link">
    <inertial>
      <origin
        xyz="-0.25509556705506 1.70188344306155E-07 0.00956131679620198"
        rpy="0 0 0" />
      <mass
        value="1476.38884748495" />
      <inertia
        ixx="283.612482002626"
        ixy="-0.000250094122819586"
        ixz="0.219788395429889"
        iyy="201.076576743826"
        iyz="-1.46698386887134E-05"
        izz="139.717141754839" />
    </inertial>
    <visual>
      <origin
        xyz="0 0 0"
        rpy="0 0 0" />
      <geometry>
        <mesh
          filename="package://F4-1000C/meshes/base_link.STL" />
      </geometry>
      <material
        name="">
        <color
          rgba="0.898039215686275 0.917647058823529 0.929411764705882 1" />
      </material>
    </visual>
    <collision>
      <origin
        xyz="0 0 0"
        rpy="0 0 0" />
      <geometry>
        <mesh
          filename="package://F4-1000C/meshes/base_link.STL" />
      </geometry>
    </collision>
  </link>
  <link
    name="left-front-wheel">
    <inertial>
      <origin
        xyz="-5.55111512312578E-17 0 -3.46944695195361E-18"
        rpy="0 0 0" />
      <mass
        value="1.28970297294905" />
      <inertia
        ixx="0.0025481102243417"
        ixy="6.48729109351191E-19"
        ixz="-1.70192636025912E-20"
        iyy="0.00457500887321458"
        iyz="2.39463127818459E-19"
        izz="0.0025481102243417" />
    </inertial>
    <visual>
      <origin
        xyz="0 0 0"
        rpy="0 0 0" />
      <geometry>
        <mesh
          filename="package://F4-1000C/meshes/left-front-wheel.STL" />
      </geometry>
      <material
        name="">
        <color
          rgba="0.298039215686275 0.298039215686275 0.298039215686275 1" />
      </material>
    </visual>
    <collision>
      <origin
        xyz="0 0 0"
        rpy="0 0 0" />
      <geometry>
        <mesh
          filename="package://F4-1000C/meshes/left-front-wheel.STL" />
      </geometry>
    </collision>
  </link>
  <joint
    name="left-front-wheel"
    type="continuous">
    <origin
      xyz="-0.15 0.345 -0.57"
      rpy="0 0 0" />
    <parent
      link="base_link" />
    <child
      link="left-front-wheel" />
    <axis
      xyz="0 1 0" />
  </joint>
  <link
    name="right-front-wheel">
    <inertial>
      <origin
        xyz="-2.7756E-17 1.1102E-16 -3.4694E-18"
        rpy="0 0 0" />
      <mass
        value="1.2897" />
      <inertia
        ixx="0.0025481"
        ixy="8.9182E-20"
        ixz="-1.4535E-35"
        iyy="0.004575"
        iyz="-1.0072E-34"
        izz="0.0025481" />
    </inertial>
    <visual>
      <origin
        xyz="0 0 0"
        rpy="0 0 0" />
      <geometry>
        <mesh
          filename="package://F4-1000C/meshes/right-front-wheel.STL" />
      </geometry>
      <material
        name="">
        <color
          rgba="0.29804 0.29804 0.29804 1" />
      </material>
    </visual>
    <collision>
      <origin
        xyz="0 0 0"
        rpy="0 0 0" />
      <geometry>
        <mesh
          filename="package://F4-1000C/meshes/right-front-wheel.STL" />
      </geometry>
    </collision>
  </link>
  <joint
    name="right-front-wheel"
    type="continuous">
    <origin
      xyz="-0.15 -0.345 -0.57"
      rpy="0 0 0" />
    <parent
      link="base_link" />
    <child
      link="right-front-wheel" />
    <axis
      xyz="0 1 0" />
  </joint>
  <link
    name="left-back-wheel">
    <inertial>
      <origin
        xyz="9.8261E-19 -2.7756E-17 -3.4694E-18"
        rpy="0 0 0" />
      <mass
        value="1.2897" />
      <inertia
        ixx="0.0025481"
        ixy="5.137E-19"
        ixz="-9.962E-35"
        iyy="0.004575"
        iyz="-3.9307E-19"
        izz="0.0025481" />
    </inertial>
    <visual>
      <origin
        xyz="0 0 0"
        rpy="0 0 0" />
      <geometry>
        <mesh
          filename="package://F4-1000C/meshes/left-back-wheel.STL" />
      </geometry>
      <material
        name="">
        <color
          rgba="0.29804 0.29804 0.29804 1" />
      </material>
    </visual>
    <collision>
      <origin
        xyz="0 0 0"
        rpy="0 0 0" />
      <geometry>
        <mesh
          filename="package://F4-1000C/meshes/left-back-wheel.STL" />
      </geometry>
    </collision>
  </link>
  <joint
    name="left-back-wheel"
    type="continuous">
    <origin
      xyz="-0.4 0.345 -0.57"
      rpy="0 0 0" />
    <parent
      link="base_link" />
    <child
      link="left-back-wheel" />
    <axis
      xyz="0 1 0" />
  </joint>
  <link
    name="right-back-wheel">
    <inertial>
      <origin
        xyz="1.67904392943369E-18 0 -3.46944695195361E-18"
        rpy="0 0 0" />
      <mass
        value="1.28970297294906" />
      <inertia
        ixx="0.0025481102243417"
        ixy="-1.42114941576933E-18"
        ixz="6.54587061638121E-21"
        iyy="0.00457500887321459"
        iyz="6.04461613839555E-20"
        izz="0.0025481102243417" />
    </inertial>
    <visual>
      <origin
        xyz="0 0 0"
        rpy="0 0 0" />
      <geometry>
        <mesh
          filename="package://F4-1000C/meshes/right-back-wheel.STL" />
      </geometry>
      <material
        name="">
        <color
          rgba="0.298039215686275 0.298039215686275 0.298039215686275 1" />
      </material>
    </visual>
    <collision>
      <origin
        xyz="0 0 0"
        rpy="0 0 0" />
      <geometry>
        <mesh
          filename="package://F4-1000C/meshes/right-back-wheel.STL" />
      </geometry>
    </collision>
  </link>
  <joint
    name="right-back-wheel"
    type="continuous">
    <origin
      xyz="-0.4 -0.345 -0.57"
      rpy="0 0 0" />
    <parent
      link="base_link" />
    <child
      link="right-back-wheel" />
    <axis
      xyz="0 1 0" />
  </joint>
  <link
    name="fork">
    <inertial>
      <origin
        xyz="0.551768666736432 -3.88578058618805E-16 -0.565"
        rpy="0 0 0" />
      <mass
        value="90.9244280027149" />
      <inertia
        ixx="0.333123743141706"
        ixy="6.05644313946917E-15"
        ixz="-5.55887444166568E-18"
        iyy="11.0420920443029"
        iyz="3.70273279902964E-18"
        izz="11.3009608379091" />
    </inertial>
    <visual>
      <origin
        xyz="0 0 0"
        rpy="0 0 0" />
      <geometry>
        <mesh
          filename="package://F4-1000C/meshes/fork.STL" />
      </geometry>
      <material
        name="">
        <color
          rgba="0.898039215686275 0.917647058823529 0.929411764705882 1" />
      </material>
    </visual>
    <collision>
      <origin
        xyz="0 0 0"
        rpy="0 0 0" />
      <geometry>
        <mesh
          filename="package://F4-1000C/meshes/fork.STL" />
      </geometry>
    </collision>
  </link>
  <joint
    name="fork-lift"
    type="prismatic">
    <origin
      xyz="0 0 0"
      rpy="0 0 0" />
    <parent
      link="base_link" />
    <child
      link="fork" />
    <axis
      xyz="0 0 -1" />
    <limit
      lower="-2"
      upper="0"
      effort="0"
      velocity="0" />
  </joint>
</robot>